<?xml version="1.0"?>
<robot name="my_robot" xmlns:xacro="http://www.ros.org/wiki/xacro">

  <!-- ================= -->
  <!-- Properties/Macros -->
  <!-- ================= -->
  <xacro:property name="base_width" value="0.4"/>
  <xacro:property name="base_length" value="0.5"/>
  <xacro:property name="base_height" value="0.1"/>
  
  <xacro:property name="wheel_radius" value="0.1"/>
  <xacro:property name="wheel_width" value="0.05"/>
  <xacro:property name="wheel_separation" value="0.4"/>
  
  <xacro:property name="caster_radius" value="0.02"/>
  
  <!-- Colors -->
  <material name="blue">
    <color rgba="0 0 0.8 1"/>
  </material>
  <material name="black">
    <color rgba="0 0 0 1"/>
  </material>
  <material name="grey">
    <color rgba="0.5 0.5 0.5 1"/>
  </material>

  <!-- ============= -->
  <!-- Base Link -->
  <!-- ============= -->
  <link name="base_link">
    <inertial>
      <mass value="2.0"/>
      <inertia ixx="0.02" ixy="0.0" ixz="0.0" iyy="0.03" iyz="0.0" izz="0.02"/>
    </inertial>
    <visual>
      <geometry>
        <box size="${base_length} ${base_width} ${base_height}"/>
      </geometry>
      <material name="blue"/>
    </visual>
    <collision>
      <geometry>
        <box size="${base_length} ${base_width} ${base_height}"/>
      </geometry>
    </collision>
  </link>

  <!-- ============= -->
  <!-- Left Wheel -->
  <!-- ============= -->
  <link name="left_wheel">
    <inertial>
      <mass value="0.5"/>
      <inertia ixx="0.001" ixy="0.0" ixz="0.0" iyy="0.001" iyz="0.0" izz="0.001"/>
    </inertial>
    <visual>
      <geometry>
        <cylinder radius="${wheel_radius}" length="${wheel_width}"/>
      </geometry>
      <material name="black"/>
    </visual>
    <collision>
      <geometry>
        <cylinder radius="${wheel_radius}" length="${wheel_width}"/>
      </geometry>
    </collision>
  </link>

  <!-- ============= -->
  <!-- Right Wheel -->
  <!-- ============= -->
  <link name="right_wheel">
    <inertial>
      <mass value="0.5"/>
      <inertia ixx="0.001" ixy="0.0" ixz="0.0" iyy="0.001" iyz="0.0" izz="0.001"/>
    </inertial>
    <visual>
      <geometry>
        <cylinder radius="${wheel_radius}" length="${wheel_width}"/>
      </geometry>
      <material name="black"/>
    </visual>
    <collision>
      <geometry>
        <cylinder radius="${wheel_radius}" length="${wheel_width}"/>
      </geometry>
    </collision>
  </link>

  <!-- ============= -->
  <!-- Front Caster -->
  <!-- ============= -->
  <link name="front_caster">
    <inertial>
      <mass value="0.1"/>
      <inertia ixx="0.0001" ixy="0.0" ixz="0.0" iyy="0.0001" iyz="0.0" izz="0.0001"/>
    </inertial>
    <visual>
      <geometry>
        <sphere radius="${caster_radius}"/>
      </geometry>
      <material name="grey"/>
    </visual>
    <collision>
      <geometry>
        <sphere radius="${caster_radius}"/>
      </geometry>
    </collision>
  </link>

  <!-- ============= -->
  <!-- Back Caster -->
  <!-- ============= -->
  <link name="back_caster">
    <inertial>
      <mass value="0.1"/>
      <inertia ixx="0.0001" ixy="0.0" ixz="0.0" iyy="0.0001" iyz="0.0" izz="0.0001"/>
    </inertial>
    <visual>
      <geometry>
        <sphere radius="${caster_radius}"/>
      </geometry>
      <material name="grey"/>
    </visual>
    <collision>
      <geometry>
        <sphere radius="${caster_radius}"/>
      </geometry>
    </collision>
  </link>

  <!-- ============= -->
  <!-- Joints -->
  <!-- ============= -->
  <joint name="left_wheel_joint" type="continuous">
    <parent link="base_link"/>
    <child link="left_wheel"/>
    <origin xyz="0 ${wheel_separation/2} -${base_height/2}" rpy="-${pi/2} 0 0"/>
    <axis xyz="0 1 0"/>
    <dynamics damping="0.1" friction="0.1"/>
  </joint>

  <joint name="right_wheel_joint" type="continuous">
    <parent link="base_link"/>
    <child link="right_wheel"/>
    <origin xyz="0 -${wheel_separation/2} -${base_height/2}" rpy="-${pi/2} 0 0"/>
    <axis xyz="0 1 0"/>
    <dynamics damping="0.1" friction="0.1"/>
  </joint>

  <joint name="front_caster_joint" type="fixed">
    <parent link="base_link"/>
    <child link="front_caster"/>
    <origin xyz="${base_length/2 - caster_radius} 0 -${base_height/2 + caster_radius}"/>
  </joint>

  <joint name="back_caster_joint" type="fixed">
    <parent link="base_link"/>
    <child link="back_caster"/>
    <origin xyz="-${base_length/2 + caster_radius} 0 -${base_height/2 + caster_radius}"/>
  </joint>

  <!-- ========================= -->
  <!-- Direct Gazebo Diff Drive Plugin -->
  <!-- ========================= -->
  <gazebo>
    <plugin name="diff_drive_controller" filename="libgazebo_ros_diff_drive.so">
      <ros>
        <namespace>/</namespace>
      </ros>
      <left_joint>left_wheel_joint</left_joint>
      <right_joint>right_wheel_joint</right_joint>
      <wheel_separation>${wheel_separation}</wheel_separation>
      <wheel_diameter>${wheel_radius*2}</wheel_diameter>
      <max_wheel_torque>20</max_wheel_torque>
      <max_wheel_acceleration>10.0</max_wheel_acceleration>
      <command_topic>/cmd_vel</command_topic>
      <odometry_topic>/odom</odometry_topic>
      <odometry_frame>odom</odometry_frame>
      <robot_base_frame>base_link</robot_base_frame>
      <publish_odom>true</publish_odom>
      <publish_odom_tf>true</publish_odom_tf>
      <publish_wheel_tf>true</publish_wheel_tf>
    </plugin>
  </gazebo>

  <!-- Add color to Gazebo -->
  <gazebo reference="base_link">
    <material>Gazebo/Blue</material>
  </gazebo>
  
  <gazebo reference="left_wheel">
    <material>Gazebo/Black</material>
  </gazebo>
  
  <gazebo reference="right_wheel">
    <material>Gazebo/Black</material>
  </gazebo>
  
  <gazebo reference="front_caster">
    <material>Gazebo/Grey</material>
  </gazebo>
  
  <gazebo reference="back_caster">
    <material>Gazebo/Grey</material>
  </gazebo>

</robot>
