<?xml version="1.0"?>
<robot name="my_robot">
  
  <!-- Base link -->
  <link name="base_link">
    <visual>
      <geometry>
        <box size="0.4 0.3 0.1"/>
      </geometry>
      <material name="blue">
        <color rgba="0 0 0.8 1"/>
      </material>
    </visual>
    <collision>
      <geometry>
        <box size="0.4 0.3 0.1"/>
      </geometry>
    </collision>
    <inertial>
      <mass value="1.0"/>
      <inertia ixx="0.01" ixy="0" ixz="0" iyy="0.01" iyz="0" izz="0.01"/>
    </inertial>
  </link>

  <!-- Left wheel -->
  <link name="left_wheel">
    <visual>
      <geometry>
        <cylinder radius="0.05" length="0.05"/>
      </geometry>
      <material name="black">
        <color rgba="0 0 0 1"/>
      </material>
    </visual>
    <collision>
      <geometry>
        <cylinder radius="0.05" length="0.05"/>
      </geometry>
    </collision>
    <inertial>
      <mass value="0.1"/>
      <inertia ixx="0.0001" ixy="0" ixz="0" iyy="0.0001" iyz="0" izz="0.0001"/>
    </inertial>
  </link>

  <!-- Right wheel -->
  <link name="right_wheel">
    <visual>
      <geometry>
        <cylinder radius="0.05" length="0.05"/>
      </geometry>
      <material name="black">
        <color rgba="0 0 0 1"/>
      </material>
    </visual>
    <collision>
      <geometry>
        <cylinder radius="0.05" length="0.05"/>
      </geometry>
    </collision>
    <inertial>
      <mass value="0.1"/>
      <inertia ixx="0.0001" ixy="0" ixz="0" iyy="0.0001" iyz="0" izz="0.0001"/>
    </inertial>
  </link>

  <!-- Joints -->
  <joint name="base_to_left_wheel" type="continuous">
    <parent link="base_link"/>
    <child link="left_wheel"/>
    <origin xyz="-0.1 0.15 0" rpy="0 1.5708 0"/>
    <axis xyz="0 0 1"/>
  </joint>

  <joint name="base_to_right_wheel" type="continuous">
    <parent link="base_link"/>
    <child link="right_wheel"/>
    <origin xyz="-0.1 -0.15 0" rpy="0 1.5708 0"/>
    <axis xyz="0 0 1"/>
  </joint>

  <!-- Gazebo Harmonic plugin - DIFFERENT from Classic! -->
  <gazebo>
    <plugin filename="gz_ros2_control-system" name="gz_ros2_control::GazeboSimSystem">
      <parameters>$(find my_robot_harmonic)/config/ros2_control.yaml</parameters>
    </plugin>
  </gazebo>
</robot>